Traceback (most recent call last):
  File "C:\Users\Josue\anaconda3\Lib\site-packages\jupyter_cache\executors\utils.py", line 58, in single_nb_execution
    executenb(
  File "C:\Users\Josue\anaconda3\Lib\site-packages\nbclient\client.py", line 1305, in execute
    return NotebookClient(nb=nb, resources=resources, km=km, **kwargs).execute()
           ^^^^^^^^^^^^^^^^^^^^^^^^^^^^^^^^^^^^^^^^^^^^^^^^^^^^^^^^^^^^^^^^^^^^^
  File "C:\Users\Josue\anaconda3\Lib\site-packages\jupyter_core\utils\__init__.py", line 173, in wrapped
    return loop.run_until_complete(inner)
           ^^^^^^^^^^^^^^^^^^^^^^^^^^^^^^
  File "C:\Users\Josue\anaconda3\Lib\asyncio\base_events.py", line 653, in run_until_complete
    return future.result()
           ^^^^^^^^^^^^^^^
  File "C:\Users\Josue\anaconda3\Lib\site-packages\nbclient\client.py", line 705, in async_execute
    await self.async_execute_cell(
  File "C:\Users\Josue\anaconda3\Lib\site-packages\nbclient\client.py", line 1058, in async_execute_cell
    await self._check_raise_for_error(cell, cell_index, exec_reply)
  File "C:\Users\Josue\anaconda3\Lib\site-packages\nbclient\client.py", line 914, in _check_raise_for_error
    raise CellExecutionError.from_cell_and_msg(cell, exec_reply_content)
nbclient.exceptions.CellExecutionError: An error occurred while executing the following cell:
------------------
# Import relevant packages
import pandas as pd
import numpy as np
import matplotlib.pyplot as plt
import seaborn as sns
import warnings
from sklearn.utils import resample
from sklearn.model_selection import train_test_split, cross_val_score, cross_val_predict, KFold
from sklearn.pipeline import make_pipeline
from sklearn.linear_model import LassoCV, RidgeCV, ElasticNetCV, LinearRegression, Ridge, Lasso, LogisticRegressionCV
from sklearn.preprocessing import StandardScaler
from sklearn.ensemble import RandomForestRegressor, RandomForestClassifier, GradientBoostingRegressor
from sklearn.tree import DecisionTreeRegressor
import statsmodels.api as sm
import statsmodels.formula.api as smf
from econml.sklearn_extensions.linear_model import WeightedLasso
import patsy
warnings.simplefilter('ignore')

# Set random seed for reproducibility
np.random.seed(123)
------------------


[1;31m---------------------------------------------------------------------------[0m
[1;31mModuleNotFoundError[0m                       Traceback (most recent call last)
Cell [1;32mIn[1], line 16[0m
[0;32m     14[0m [38;5;28;01mimport[39;00m [38;5;21;01mstatsmodels[39;00m[38;5;21;01m.[39;00m[38;5;21;01mapi[39;00m [38;5;28;01mas[39;00m [38;5;21;01msm[39;00m
[0;32m     15[0m [38;5;28;01mimport[39;00m [38;5;21;01mstatsmodels[39;00m[38;5;21;01m.[39;00m[38;5;21;01mformula[39;00m[38;5;21;01m.[39;00m[38;5;21;01mapi[39;00m [38;5;28;01mas[39;00m [38;5;21;01msmf[39;00m
[1;32m---> 16[0m [38;5;28;01mfrom[39;00m [38;5;21;01meconml[39;00m[38;5;21;01m.[39;00m[38;5;21;01msklearn_extensions[39;00m[38;5;21;01m.[39;00m[38;5;21;01mlinear_model[39;00m [38;5;28;01mimport[39;00m WeightedLasso
[0;32m     17[0m [38;5;28;01mimport[39;00m [38;5;21;01mpatsy[39;00m
[0;32m     18[0m warnings[38;5;241m.[39msimplefilter([38;5;124m'[39m[38;5;124mignore[39m[38;5;124m'[39m)

[1;31mModuleNotFoundError[0m: No module named 'econml'

